<mujoco model="ROPUK V2">
    <visual>
      <rgba rangefinder="1 0.7 0.3 0.1"/>
    </visual>

    <worldbody>
        <body name="RopukV2" pos="1.4 0.8 0.1">
        <joint type="free"/>
        <body name="chassis" pos="0 0 0">
            <!-- Base -->
            <!-- Level 1 -->
            <geom type="box" size="0.1145 0.0625 0.0025" pos="0  0    0"/>
            <geom type="box" size="0.15   0.0575 0.0025" pos="0 -0.12 0"/>
            <geom type="box" size="0.15   0.0575 0.0025" pos="0  0.12 0"/>
            <!-- Level 2 -->
            <geom type="box" size="0.1145 0.0625 0.0025" pos="0  0    0.07"/>
            <geom type="box" size="0.15   0.0575 0.0025" pos="0 -0.12 0.07"/>
            <geom type="box" size="0.15   0.0575 0.0025" pos="0  0.12 0.07"/>
            <!-- Level 3 -->
            <geom type="box" size="0.125 0.08 0.0025" pos="0 0 0.14"/>
            
            <!-- Spacer -->
            <!-- Wheels -->
            <geom type="cylinder" size="0.005 0.035" pos=" 0.09157433   0.02711085 0.035"/>
            <geom type="cylinder" size="0.005 0.035" pos="-0.09157433   0.02711085 0.035"/>
            <geom type="cylinder" size="0.005 0.035" pos=" 0.09157433  -0.02711085 0.035"/>
            <geom type="cylinder" size="0.005 0.035" pos="-0.09157433  -0.02711085 0.035"/>
            
            <!-- Base Spacer Level 1-2 -->
            <geom type="cylinder" size="0.005 0.035" pos=" -0.14  0.165 0.035"/>
            <geom type="cylinder" size="0.005 0.035" pos="  0.14  0.165 0.035"/>
            <geom type="cylinder" size="0.005 0.035" pos=" -0.14  0.075 0.035"/>
            <geom type="cylinder" size="0.005 0.035" pos="  0.14  0.075 0.035"/>
            <geom type="cylinder" size="0.005 0.035" pos=" -0.14 -0.165 0.035"/>
            <geom type="cylinder" size="0.005 0.035" pos="  0.14 -0.165 0.035"/>
            <geom type="cylinder" size="0.005 0.035" pos=" -0.14 -0.075 0.035"/>
            <geom type="cylinder" size="0.005 0.035" pos="  0.14 -0.075 0.035"/>
            <!-- Base Spacer Level 2-3 -->
            <geom type="cylinder" size="0.005 0.035" pos=" 0.115  0.07 0.105"/>
            <geom type="cylinder" size="0.005 0.035" pos="-0.115  0.07 0.105"/>
            <geom type="cylinder" size="0.005 0.035" pos=" 0.115 -0.07 0.105"/>
            <geom type="cylinder" size="0.005 0.035" pos="-0.115 -0.07 0.105"/>

            <!-- Arrow -->
            <geom type="box" size="0.005 0.04 0.001" pos=" 0  -0.125 0.072" rgba="1 0 0 1"/>
            <geom type="box" size="0.005 0.03 0.001" pos="0.018  -0.15 0.072" euler="0 0 -45" rgba="1 0 0 1"/>
            <geom type="box" size="0.005 0.03 0.001" pos="-0.018  -0.15 0.072" euler="0 0 45" rgba="1 0 0 1"/>
        </body>
        
        <!-- Lidar -->
        <body name="lidar" pos="0 0 0.14">
            <geom type="cylinder" size="0.02 0.01" pos="0 0 0.01" rgba="0 0 0 1"/>
            <body name="lasers" pos="0 0 0.01" euler="90 90 0" >
                <replicate count="360" euler="0 1 0">   
                    <site name="rf" size="0.001 0.001 0.001" rgba="0 0 0 0" pos=".021 0 0" zaxis="1 0 0"/>
                </replicate>
            </body>
        </body>
        <!-- End Lidar -->

        <!-- Free Wheels -->
        <geom type="cylinder" size="0.02 0.005" pos="0.095 0.11732082 -0.005"/>
        <body name="free_wheel1" pos="0.095 0.11732082 -0.0125">
            <joint type="ball" name="fw1"/>
            <geom type="sphere" size="0.01"/>
        </body>

        <geom type="cylinder" size="0.02 0.005" pos="0.095 -0.11732082 -0.005"/>
        <body name="free_wheel2" pos="0.095 -0.11732082 -0.0125">
            <joint type="ball" name="fw2"/>
            <geom type="sphere" size="0.01"/>
        </body>

        <geom type="cylinder" size="0.02 0.005" pos="-0.095 0.11732082 -0.005"/>
        <body name="free_wheel3" pos="-0.095 0.11732082 -0.0125">
            <joint type="ball" name="fw3"/>
            <geom type="sphere" size="0.01"/>
        </body>

        <geom type="cylinder" size="0.02 0.005" pos="-0.095 -0.11732082 -0.005"/>
        <body name="free_wheel4" pos="-0.095 -0.11732082 -0.0125">
            <joint type="ball" name="fw4"/>
            <geom type="sphere" size="0.01"/>
        </body>
        <!-- End Free Wheels -->

        <!-- Motors -->
        <body name="wheel1" pos="0.0995 0 0.03">
            <joint type="slide" name="spring1" axis="0 0 1" damping="0.5" range="-0.015 0.025"/>
            <geom type="box" size="0.015 0.045 0.015" pos="0 0 0"/>
            <geom type="cylinder" size="0.005 0.0028" pos="0.015 0 0" euler="0 90 0" rgba="0 0 0 1"/>
            <body name="motor1">
                <geom type="cylinder" size="0.05 0.0215" pos="0.0393 0 0" euler="0 90 0" rgba="0 0 0 1"/>
                <joint name="wheel1_motor" type="hinge" damping="0.5" pos="0.0393 0 0" axis="1 0 0"/>
            </body>
        </body>

        <body name="wheel2" pos="-0.0995 0 0.03" euler="0 0 180">
            <joint type="slide" name="spring2" axis="0 0 1" damping="0.5" range="-0.015 0.025"/>
            <geom type="box" size="0.015 0.045 0.015" pos="0 0 0"/>
            <geom type="cylinder" size="0.005 0.0028" pos="0.015 0 0" euler="0 90 0" rgba="0 0 0 0.6"/>
            <body name="motor2">
                <geom type="cylinder" size="0.05 0.0215" pos="0.0393 0 0" euler="0 90 0" rgba="0 0 0 0.6"/>
                <joint name="wheel2_motor" type="hinge" damping="0.5" pos="0.0393 0 0" axis="-1 0 0"/>
            </body>
        </body>
        <!-- End Motors -->
    </body>
    </worldbody>

<sensor>
  <rangefinder name="rngfndr" site="rf"/>
</sensor>

<actuator>
    <velocity joint="wheel1_motor" kv="0.15" ctrllimited="true" ctrlrange="-50 50"/>
    <velocity joint="wheel2_motor" kv="0.15" ctrllimited="true" ctrlrange="-50 50"/>
</actuator>
</mujoco>
